Workbook

Sheet COVER
B2: LH REAL ESTATE ADVISORY · INVESTMENT · RESEARCH
B5: KHU PHỨC HỢP CĂN HỘ CAO TẦNG
B6: BÁO CÁO NGHIÊN CỨU KHẢ THI · FEASIBILITY STUDY
B7: Phạm Văn Đồng
B9: Prepared for | C9: Chủ đầu tư
B10: Prepared by | C10: LH Real Estate Advisory
B11: Ngày phát hành | C11: 23/7/2026
B12: STRICTLY PRIVATE & CONFIDENTIAL
B14: TÓM TẮT HIỆU QUẢ ĐẦU TƯ
B15: Kết luận đầu tư | C15: CHƯA ĐẠT NGƯỠNG
B16: NPV chủ đầu tư @12%/năm | C16: -1.1934467e+11 | D16: tr.đ
B17: IRR chủ đầu tư (levered) | C17: 0.0029682969
B18: IRR dự án — TMĐT (unlevered) | C18: 0.0023958359
B19: Thời gian hoàn vốn | C19: 4 năm
B20: Lợi nhuận sau thuế hợp nhất | C20: 6.8678296e+10 | D20: tr.đ
B21: Tổng mức đầu tư (gồm lãi vay) | C21: 1.231766e+12 | D21: tr.đ
B23: NỘI DUNG WORKBOOK
B24: DASHBOARD | C24: Bảng điều khiển: hiệu quả, cơ cấu vốn, dòng tiền, kiểm tra toàn vẹn
B25: INPUT | C25: Thông số đầu vào — sửa trực tiếp (web đọc theo địa chỉ ô)
B26: TIENDO | C26: Tiến độ giải ngân chi phí theo năm
B27: QD425 | C27: Khái toán suất vốn đầu tư — QĐ 425/QĐ-BXD
B28: FS | C28: Dòng tiền hợp nhất & hiệu quả (giá trị, không vòng lặp)
B29: CAUTRUCVON | C29: Cơ cấu vốn & nguồn tiền tài trợ theo năm (liên kết FS)
B30: PHANBOCP | C30: Cơ cấu phân bổ chi phí Bán hàng / Cho thuê (theo cơ sở phân bổ)
B31: KHAITOAN | C31: Đối chiếu khái toán & hạ tầng kỹ thuật
B32: HDSD | C32: Hướng dẫn sử dụng workbook
B34: Tài liệu do LH Real Estate Advisory lập trên cơ sở giả định của chủ đầu tư; phục vụ phân tích nội bộ, không phải khuyến nghị đầu tư. Số liệu lấy trực tiếp từ engine định lượng — DASHBOARD & FS luôn khớp web.

Sheet DASHBOARD
B1: DASHBOARD HIỆU QUẢ DỰ ÁN — Khu phức hợp căn hộ cao tầng
B3: KẾT LUẬN | C3: CHƯA ĐẠT NGƯỠNG
B5: CHỈ TIÊU HIỆU QUẢ (hợp nhất bán + cho thuê)
B6: NPV chủ đầu tư @12%/năm | C6: -1.1934467e+11 | D6: tr.đ
B7: IRR chủ đầu tư | C7: 0.0029682969
B8: IRR dự án (TMĐT) | C8: 0.0023958359
B9: Thời gian hoàn vốn | C9: 4 năm
B10: Lợi nhuận sau thuế hợp nhất | C10: 6.8678296e+10 | D10: tr.đ
B11: Thuế TNDN hợp nhất (bù lỗ 5 năm) | C11: 1.7169574e+10 | D11: tr.đ
B13: CƠ CẤU TỔNG MỨC ĐẦU TƯ
B14: Đất & pháp lý | C14: 7.4907e+11 | D14: 0.60812685 | E14: ██████████████████████████████
B15: Xây dựng (gồm VAT) | C15: 4.4376567e+11 | D15: 0.36026783 | E15: ██████████████████
B16: Lãi vay vốn hoá | C16: 38930360154 | D16: 0.03160532 | E16: ██
B17: TỔNG MỨC ĐẦU TƯ (gồm lãi vay) | C17: 1.231766e+12 | D17: 1
B19: CƠ CẤU NGUỒN VỐN
B20: Vốn vay ngân hàng | C20: 512984969875 | D20: 0.43005502 | E20: ██████████████████████████
B21: Vốn chủ sở hữu | C21: 5.9628173e+11 | D21: 0.4998859 | E21: ██████████████████████████████
B22: Vốn huy động khách hàng | C22: 8.3568969e+10 | D22: 0.070059079 | E22: ████
B24: CƠ CẤU NGUỒN VỐN THEO RỔ CHI PHÍ
B25: Rổ chi phí | C25: Tổng (triệu) | D25: Vốn chủ | E25: Vay NH / Huy động KH
B26: Chi phí đầu tư — TMĐT (chưa lãi vay) | C26: 1.1928357e+12 | D26: 3.1032089e+11 | E26: Vay 513 · KH 370
B27: Lãi vay vốn hoá (vốn chủ tài trợ) | C27: 38930360154 | D27: 38930360154 | E27: Vay 0 · KH 0
B28: Chi phí hoạt động + VAT | C28: 3.1930011e+11 | D28: 0 | E28: Vay 0 · KH 319
B29: Thuế TNDN | C29: 1.7169574e+10 | D29: 0 | E29: Vay 0 · KH 17
B30: TỔNG NGUỒN | C30: 1.5682357e+12 | D30: 3.4925125e+11 | E30: Vay 513 · KH 706
B31: Tỷ trọng (VC / Vay / KH) | C31: 0.22270329 | D31: 0.32710961 | E31: 45.0% · WACC 12.0% (vốn có CP)
B32: Lãi vay vốn hoá (đã gồm trong rổ đầu tư) | C32: 38930360154
B34: DÒNG TIỀN CHỦ ĐẦU TƯ THEO NĂM
B35: Năm | C35: Ngân lưu CĐT (triệu) | E35: Biểu đồ (|giá trị|)
B36: 2026 | C36: -200000000000 | E36: (−) █████████████████████
B37: 2027 | C37: -215000000000 | E37: (−) ██████████████████████
B38: 2028 | C38: -76428219366 | E38: (−) ████████
B39: 2029 | C39: 2.448199e+11 | E39: █████████████████████████
B40: 2030 | C40: 2.5064552e+11 | E40: ██████████████████████████
B41: 2031 | C41: 0
B42: 2032 | C42: 0
B43: 2033 | C43: 0
B44: 2034 | C44: 0
B45: 2035 | C45: 0
B46: 2036 | C46: 0
...

Sheet INPUT
A1: FS INPUT — CHỈ SỬA GIÁ TRỊ CỘT C..F, KHÔNG CHÈN/XÓA HÀNG (web đọc theo địa chỉ ô)
B3: THAM SỐ CHUNG
B4: Tỷ suất chiết khấu CĐT (r) | C4: 12 | D4: %/năm
B5: Lãi suất vay ngân hàng | C5: 12 | D5: %/năm
B6: Thuế VAT | C6: 10 | D6: %
B7: Thuế TNDN | C7: 20 | D7: %
B8: Thuế TNDN tạm nộp/dòng thu | C8: 1 | D8: %
B9: Tốc độ tăng giá bán | C9: 5 | D9: %/năm
B10: Tổng diện tích đất dự án | C10: 3545 | D10: m2
B11: Diện tích đất xây dựng | C11: 1500 | D11: m2
B12: Chi phí chuyển nhượng (mua đất) | C12: 400 | D12: tỷ đồng
B13: Chi phí đền bù GPMB | C13: 0 | D13: tỷ đồng
B14: Tiền sử dụng đất | C14: 289.07 | D14: tỷ đồng
B15: Quỹ nhà ở xã hội | C15: 0 | D15: tỷ đồng
... B38: Chi phí vốn huy động KH | C38: 0 | D38: %/năm
B39: THÔNG SỐ TỪNG THÁP
B40: Tên tháp | C40: Tháp 1
B41: Số tầng nổi | C41: 25 | D41: 0 | E41: 0 | F41: 0 | G41: tầng
B42: Số tầng hầm | C42: 0 | D42: 0 | E42: 0 | F42: 0 | G42: tầng
B43: GFA nổi | C43: 27696.25 | D43: 0 | E43: 0 | F43: 0 | G43: m2
B44: GFA hầm | C44: 0 | D44: 0 | E44: 0 | F44: 0 | G44: m2
B45: Sàn khối đế (shop) | C45: 2011 | D45: 0 | E45: 0 | F45: 0 | G45: m2
B46: Tỷ lệ thương phẩm căn hộ | C46: 55 | D46: 0 | E46: 0 | F46: 0 | G46: %
B47: NSA shop (thương phẩm) | C47: 1581 | D47: 0 | E47: 0 | F47: 0 | G47: m2
B48: Suất XD áp dụng (gồm VAT) | C48: 13.5 | D48: 0 | E48: 0 | F48: 0 | G48: tr.đ/m2
B49: Bảng QĐ425 (1=chung cư, 2=đa năng) | C49: 1 | D49: 0 | E49: 0 | F49: 0
B50: Mục đích (1=bán, 2=cho thuê) | C50: 1 | D50: 0 | E50: 0 | F50: 0
B51: THAM SỐ MỞ RỘNG V3
B52: Chiều cao trung bình 1 tầng | C52: 3.5 | D52: m
B54: Phương pháp vay: 1=giải ngân thực tế, 2=hạn mức cơ cấu vay | C54: 2
B55: Hệ số vùng Kkv (QĐ 409/QĐ-BXD) | C55: 1 | D55: lần
B56: Hệ số thời điểm Ktg | C56: 1 | D56: lần
B57: THÔNG TIN DỰ ÁN
B58: Tên dự án | C58: Khu phức hợp căn hộ cao tầng
B59: Vị trí | C59: Phạm Văn Đồng
B60: Chủ đầu tư
B61: Đơn vị lập báo cáo
B62: Loại hình dự án | C62: Chung cư nhà ở thương mại
B63: Ghi chú pháp lý
B64: Vốn chủ: 1=tự động theo waterfall, 2=cố định theo ô C25 | C64: 1
...

Sheet TIENDO
A1: TIẾN ĐỘ (%) — KHÔNG CHÈN/XÓA HÀNG CỘT
B2: Năm | C2: 2026 | D2: 2027 | E2: 2028 | F2: 2029 | G2: 2030 | H2: 2031 | I2: 2032 | J2: 2033 | K2: 2034 | L2: 2035 | M2: 2036 | N2: 2037 | O2: 2038
A3: TIẾN ĐỘ CHI PHÍ | B3: Chi phí chuyển nhượng | C3: 50 | D3: 50 | E3: 0 | F3: 0 | G3: 0 | H3: 0 | I3: 0 | J3: 0 | K3: 0 | L3: 0 | M3: 0 | N3: 0 | O3: 0
B4: Đền bù GPMB | C4: 0 | D4: 0 | E4: 100 | F4: 0 | G4: 0 | H4: 0 | I4: 0 | J4: 0 | K4: 0 | L4: 0 | M4: 0 | N4: 0 | O4: 0
B5: Tiền sử dụng đất | C5: 0 | D5: 0 | E5: 100 | F5: 0 | G5: 0 | H5: 0 | I5: 0 | J5: 0 | K5: 0 | L5: 0 | M5: 0 | N5: 0 | O5: 0
B6: Chi phí pháp lý | C6: 0 | D6: 25 | E6: 25 | F6: 25 | G6: 25 | H6: 0 | I6: 0 | J6: 0 | K6: 0 | L6: 0 | M6: 0 | N6: 0 | O6: 0
B7: Hạ tầng | C7: 0 | D7: 0 | E7: 0 | F7: 50 | G7: 50 | H7: 0 | I7: 0 | J7: 0 | K7: 0 | L7: 0 | M7: 0 | N7: 0 | O7: 0
B8: Xây dựng tháp BÁN HÀNG | C8: 0 | D8: 0 | E8: 40 | F8: 50 | G8: 10 | H8: 0 | I8: 0 | J8: 0 | K8: 0 | L8: 0 | M8: 0 | N8: 0 | O8: 0
B9: Xây dựng tháp CHO THUÊ | C9: 0 | D9: 0 | E9: 100 | F9: 0 | G9: 0 | H9: 0 | I9: 0 | J9: 0 | K9: 0 | L9: 0 | M9: 0 | N9: 0 | O9: 0
B10: Tư vấn, QLDA, khác | C10: 0 | D10: 0 | E10: 40 | F10: 50 | G10: 10 | H10: 0 | I10: 0 | J10: 0 | K10: 0 | L10: 0 | M10: 0 | N10: 0 | O10: 0
B11: Dự phòng | C11: 0 | D11: 0 | E11: 40 | F11: 50 | G11: 10 | H11: 0 | I11: 0 | J11: 0 | K11: 0 | L11: 0 | M11: 0 | N11: 0 | O11: 0
A15: TIẾN ĐỘ BÁN HÀNG
B16: Căn hộ chung cư | C16: 0 | D16: 0 | E16: 40 | F16: 40 | G16: 20 | H16: 0 | I16: 0 | J16: 0 | K16: 0 | L16: 0 | M16: 0 | N16: 0 | O16: 0
B17: Shop thương mại | C17: 0 | D17: 0 | E17: 40 | F17: 40 | G17: 20 | H17: 0 | I17: 0 | J17: 0 | K17: 0 | L17: 0 | M17: 0 | N17: 0 | O17: 0
A19: MA TRẬN THU TIỀN CĂN HỘ: hàng = năm bán (vintage), cột = năm thu
B20: Căn hộ bán năm 2026 | C20: 0 | D20: 0 | E20: 0 | F20: 0 | G20: 0 | H20: 0 | I20: 0 | J20: 0 | K20: 0 | L20: 0 | M20: 0 | N20: 0 | O20: 0
B21: Căn hộ bán năm 2027 | C21: 0 | D21: 0 | E21: 0 | F21: 0 | G21: 0 | H21: 0 | I21: 0 | J21: 0 | K21: 0 | L21: 0 | M21: 0 | N21: 0 | O21: 0
B22: Căn hộ bán năm 2028 | C22: 0 | D22: 0 | E22: 30 | F22: 65 | G22: 5 | H22: 0 | I22: 0 | J22: 0 | K22: 0 | L22: 0 | M22: 0 | N22: 0 | O22: 0
B23: Căn hộ bán năm 2029 | C23: 0 | D23: 0 | E23: 0 | F23: 95 | G23: 5 | H23: 0 | I23: 0 | J23: 0 | K23: 0 | L23: 0 | M23: 0 | N23: 0 | O23: 0
B24: Căn hộ bán năm 2030 | C24: 0 | D24: 0 | E24: 0 | F24: 0 | G24: 100 | H24: 0 | I24: 0 | J24: 0 | K24: 0 | L24: 0 | M24: 0 | N24: 0 | O24: 0
B25: Căn hộ bán năm 2031 | C25: 0 | D25: 0 | E25: 0 | F25: 0 | G25: 0 | H25: 0 | I25: 0 | J25: 0 | K25: 0 | L25: 0 | M25: 0 | N25: 0 | O25: 0
B26: Căn hộ bán năm 2032 | C26: 0 | D26: 0 | E26: 0 | F26: 0 | G26: 0 | H26: 0 | I26: 0 | J26: 0 | K26: 0 | L26: 0 | M26: 0 | N26: 0 | O26: 0
B27: Căn hộ bán năm 2033 | C27: 0 | D27: 0 | E27: 0 | F27: 0 | G27: 0 | H27: 0 | I27: 0 | J27: 0 | K27: 0 | L27: 0 | M27: 0 | N27: 0 | O27: 0
B28: Căn hộ bán năm 2034 | C28: 0 | D28: 0 | E28: 0 | F28: 0 | G28: 0 | H28: 0 | I28: 0 | J28: 0 | K28: 0 | L28: 0 | M28: 0 | N28: 0 | O28: 0
B29: Căn hộ bán năm 2035 | C29: 0 | D29: 0 | E29: 0 | F29: 0 | G29: 0 | H29: 0 | I29: 0 | J29: 0 | K29: 0 | L29: 0 | M29: 0 | N29: 0 | O29: 0
B30: Căn hộ bán năm 2036 | C30: 0 | D30: 0 | E30: 0 | F30: 0 | G30: 0 | H30: 0 | I30: 0 | J30: 0 | K30: 0 | L30: 0 | M30: 0 | N30: 0 | O30: 0
B31: Căn hộ bán năm 2037 | C31: 0 | D31: 0 | E31: 0 | F31: 0 | G31: 0 | H31: 0 | I31: 0 | J31: 0 | K31: 0 | L31: 0 | M31: 0 | N31: 0 | O31: 0
B32: Căn hộ bán năm 2038 | C32: 0 | D32: 0 | E32: 0 | F32: 0 | G32: 0 | H32: 0 | I32: 0 | J32: 0 | K32: 0 | L32: 0 | M32: 0 | N32: 0 | O32: 0
A35: MA TRẬN THU TIỀN SHOPHOUSE / THƯƠNG MẠI: hàng = năm bán, cột = năm thu
B36: Shop bán năm 2026 | C36: 0 | D36: 0 | E36: 0 | F36: 0 | G36: 0 | H36: 0 | I36: 0 | J36: 0 | K36: 0 | L36: 0 | M36: 0 | N36: 0 | O36: 0
B37: Shop bán năm 2027 | C37: 0 | D37: 0 | E37: 0 | F37: 0 | G37: 0 | H37: 0 | I37: 0 | J37: 0 | K37: 0 | L37: 0 | M37: 0 | N37: 0 | O37: 0
B38: Shop bán năm 2028 | C38: 0 | D38: 0 | E38: 30 | F38: 65 | G38: 5 | H38: 0 | I38: 0 | J38: 0 | K38: 0 | L38: 0 | M38: 0 | N38: 0 | O38: 0
B39: Shop bán năm 2029 | C39: 0 | D39: 0 | E39: 0 | F39: 95 | G39: 5 | H39: 0 | I39: 0 | J39: 0 | K39: 0 | L39: 0 | M39: 0 | N39: 0 | O39: 0
B40: Shop bán năm 2030 | C40: 0 | D40: 0 | E40: 0 | F40: 0 | G40: 100 | H40: 0 | I40: 0 | J40: 0 | K40: 0 | L40: 0 | M40: 0 | N40: 0 | O40: 0
B41: Shop bán năm 2031 | C41: 0 | D41: 0 | E41: 0 | F41: 0 | G41: 0 | H41: 0 | I41: 0 | J41: 0 | K41: 0 | L41: 0 | M41: 0 | N41: 0 | O41: 0
B42: Shop bán năm 2032 | C42: 0 | D42: 0 | E42: 0 | F42: 0 | G42: 0 | H42: 0 | I42: 0 | J42: 0 | K42: 0 | L42: 0 | M42: 0 | N42: 0 | O42: 0
B43: Shop bán năm 2033 | C43: 0 | D43: 0 | E43: 0 | F43: 0 | G43: 0 | H43: 0 | I43: 0 | J43: 0 | K43: 0 | L43: 0 | M43: 0 | N43: 0 | O43: 0
B44: Shop bán năm 2034 | C44: 0 | D44: 0 | E44: 0 | F44: 0 | G44: 0 | H44: 0 | I44: 0 | J44: 0 | K44: 0 | L44: 0 | M44: 0 | N44: 0 | O44: 0
B45: Shop bán năm 2035 | C45: 0 | D45: 0 | E45: 0 | F45: 0 | G45: 0 | H45: 0 | I45: 0 | J45: 0 | K45: 0 | L45: 0 | M45: 0 | N45: 0 | O45: 0
B46: Shop bán năm 2036 | C46: 0 | D46: 0 | E46: 0 | F46: 0 | G46: 0 | H46: 0 | I46: 0 | J46: 0 | K46: 0 | L46: 0 | M46: 0 | N46: 0 | O46: 0
...

Sheet QD425
A1: SUẤT VỐN ĐẦU TƯ — QĐ 425/QĐ-BXD 30/3/2026 (1.000 đ/m2 sàn, gồm VAT). Cột A: ngưỡng số tầng (tra MATCH); B..G: SVĐT theo 0–5 hầm; H..M: CP xây dựng; N..S: CP thiết bị.
A2: Bảng 1 — Nhà chung cư (mã 11110)
A3: 1 | B3: 9202 | C3: 10529 | D3: 11175 | E3: 11793 | F3: 13024 | G3: 14247 | H3: 7784 | I3: 8931 | J3: 9448 | K3: 10002 | L3: 11046 | M3: 12082 | N3: 432 | O3: 470 | P3: 530 | Q3: 593 | R3: 654 | S3: 716
A4: 6 | B4: 10316 | C4: 11033 | D4: 11772 | E4: 12637 | F4: 13561 | G4: 14527 | H4: 8082 | I4: 8643 | J4: 9223 | K4: 9900 | L4: 10623 | M4: 11380 | N4: 724 | O4: 774 | P4: 826 | Q4: 886 | R4: 951 | S4: 1019
A5: 8 | B5: 10629 | C5: 11122 | D5: 11671 | E5: 12344 | F5: 13091 | G5: 13896 | H5: 8458 | I5: 8850 | J5: 9286 | K5: 9822 | L5: 10417 | M5: 11057 | N5: 758 | O5: 793 | P5: 832 | Q5: 881 | R5: 934 | S5: 991
A6: 11 | B6: 11132 | C6: 11450 | D6: 11829 | E6: 12320 | F6: 12883 | G6: 13512 | H6: 9041 | I6: 9301 | J6: 9608 | K6: 10006 | L6: 10465 | M6: 10975 | N6: 758 | O6: 780 | P6: 806 | Q6: 839 | R6: 877 | S6: 920
A7: 16 | B7: 12410 | C7: 12590 | D7: 12830 | E7: 13168 | F7: 13576 | G7: 14048 | H7: 9521 | I7: 9660 | J7: 9843 | K7: 10102 | L7: 10416 | M7: 10778 | N7: 1034 | O7: 1049 | P7: 1069 | Q7: 1096 | R7: 1131 | S7: 1170
A8: 21 | B8: 13818 | C8: 13923 | D8: 14083 | E8: 14335 | F8: 14655 | G8: 15037 | H8: 10611 | I8: 10691 | J8: 10814 | K8: 11008 | L8: 11255 | M8: 11548 | N8: 1367 | O8: 1377 | P8: 1393 | Q8: 1418 | R8: 1450 | S8: 1488
A9: 25 | B9: 14508 | C9: 14570 | D9: 14679 | E9: 14868 | F9: 15116 | G9: 15420 | H9: 11144 | I9: 11191 | J9: 11274 | K9: 11420 | L9: 11610 | M9: 11843 | N9: 1436 | O9: 1442 | P9: 1453 | Q9: 1472 | R9: 1496 | S9: 1526
A10: 31 | B10: 15849 | C10: 15890 | D10: 15978 | E10: 16138 | F10: 16356 | G10: 16625 | H10: 12000 | I10: 12031 | J10: 12096 | K10: 12217 | L10: 12382 | M10: 12587 | N10: 1700 | O10: 1705 | P10: 1714 | Q10: 1731 | R10: 1754 | S10: 1783
A11: 36 | B11: 17024 | C11: 17050 | D11: 17117 | E11: 17255 | F11: 17445 | G11: 17688 | H11: 12791 | I11: 12810 | J11: 12861 | K11: 12965 | L11: 13108 | M11: 13289 | N11: 1907 | O11: 1910 | P11: 1917 | Q11: 1933 | R11: 1954 | S11: 1982
A12: 41 | B12: 18197 | C12: 18216 | D12: 18276 | E12: 18401 | F12: 18577 | G12: 18803 | H12: 13581 | I12: 13596 | J12: 13641 | K12: 13733 | L12: 13866 | M12: 14035 | N12: 2113 | O12: 2116 | P12: 2122 | Q12: 2137 | R12: 2158 | S12: 2184
A13: 46 | B13: 19370 | C13: 19381 | D13: 19430 | E13: 19541 | F13: 19702 | G13: 19912 | H13: 14373 | I13: 14381 | J13: 14418 | K13: 14499 | L13: 14620 | M13: 14774 | N13: 2320 | O13: 2321 | P13: 2328 | Q13: 2341 | R13: 2360 | S13: 2386
A16: Bảng 26 — Công trình đa năng (hỗn hợp) (mã 11260)
A17: 1 | B17: 9246 | C17: 10263 | D17: 11468 | E17: 12159 | F17: 13389 | G17: 14612 | H17: 7888 | I17: 8732 | J17: 9754 | K17: 10524 | L17: 11586 | M17: 12645 | N17: 517 | O17: 598 | P17: 671 | Q17: 747 | R17: 822 | S17: 897
A18: 6 | B18: 10851 | C18: 11531 | D18: 12243 | E18: 13090 | F18: 14001 | G18: 14961 | H18: 8673 | I18: 9215 | J18: 9783 | K18: 10460 | L18: 11189 | M18: 11957 | N18: 942 | O18: 1001 | P18: 1063 | Q18: 1136 | R18: 1215 | S18: 1298
A19: 8 | B19: 11182 | C19: 11647 | D19: 12172 | E19: 12830 | F19: 13565 | G19: 13565 | H19: 9067 | I19: 9444 | J19: 9870 | K19: 10404 | L19: 11000 | M19: 11000 | N19: 976 | O19: 1017 | P19: 1063 | Q19: 1121 | R19: 1184 | S19: 1184
A20: 11 | B20: 11696 | C20: 11993 | D20: 12353 | E20: 12828 | F20: 13381 | G20: 14001 | H20: 9700 | I20: 9946 | J20: 10245 | K20: 10638 | L20: 11097 | M20: 11610 | N20: 1332 | O20: 1367 | P20: 1407 | Q20: 1461 | R20: 1525 | S20: 1595
A21: 16 | B21: 13031 | C21: 13191 | D21: 13413 | E21: 13736 | F21: 14134 | G21: 14597 | H21: 10215 | I21: 10341 | J21: 10513 | K21: 10768 | L21: 11080 | M21: 11443 | N21: 1585 | O21: 1604 | P21: 1632 | Q21: 1671 | R21: 1720 | S21: 1776
A22: 21 | B22: 14516 | C22: 14601 | D22: 14744 | E22: 14982 | F22: 15291 | G22: 15663 | H22: 11375 | I22: 11441 | J22: 11554 | K22: 11740 | L22: 11982 | M22: 12273 | N22: 1769 | O22: 1780 | P22: 1797 | Q22: 1826 | R22: 1864 | S22: 1909
A23: 25 | B23: 15240 | C23: 15285 | D23: 15380 | E23: 15556 | F23: 15794 | G23: 16087 | H23: 11954 | I23: 11990 | J23: 12064 | K23: 12202 | L23: 12388 | M23: 12619 | N23: 1860 | O23: 1866 | P23: 1878 | Q23: 1900 | R23: 1929 | S23: 1964
A24: 31 | B24: 16656 | C24: 16682 | D24: 16754 | E24: 16902 | F24: 17109 | G24: 17369 | H24: 12863 | I24: 12884 | J24: 12939 | K24: 13054 | L24: 13213 | M24: 13414 | N24: 2206 | O24: 2209 | P24: 2218 | Q24: 2238 | R24: 2266 | S24: 2300
A25: 36 | B25: 17881 | C25: 17892 | D25: 17946 | E25: 18071 | F25: 18251 | G25: 18484 | H25: 13721 | I25: 13728 | J25: 13770 | K25: 13866 | L25: 14004 | M25: 14183 | N25: 2470 | O25: 2471 | P25: 2479 | Q25: 2496 | R25: 2521 | S25: 2553
A26: 41 | B26: 19116 | C26: 19122 | D26: 19170 | E26: 19284 | F26: 19453 | G26: 19672 | H26: 14564 | I26: 14568 | J26: 14605 | K26: 14692 | L26: 14820 | M26: 14987 | N26: 2734 | O26: 2734 | P26: 2741 | Q26: 2758 | R26: 2781 | S26: 2813
A27: 46 | B27: 20340 | C27: 20342 | D27: 20385 | E27: 20492 | F27: 20650 | G27: 20858 | H27: 15420 | I27: 15423 | J27: 15454 | K27: 15535 | L27: 15656 | M27: 15812 | N27: 3010 | O27: 3010 | P27: 3016 | Q27: 3032 | R27: 3055 | S27: 3086

Sheet FS
B1: FS — MÔ HÌNH DÒNG TIỀN HỢP NHẤT · Bán hàng + Cho thuê (công thức trực tiếp · triệu đồng)
B2: Khoản mục | C2: Tổng / Giá trị | D2: 46023 | E2: 46388 | F2: 46753 | G2: 47119 | H2: 47484 | I2: 47849 | J2: 48214 | K2: 48580 | L2: 48945 | M2: 49310 | N2: 49675 | O2: 50041 | P2: 50406 | Q2: 50771 | R2: 51136 | S2: 51502 | T2: 51867 | U2: 52232 | V2: 52597 | W2: 52963 | X2: 53328 | Y2: 53693 | Z2: 54058 | AA2: 54424 | AB2: 54789 | AC2: 55154 | AD2: 55519 | AE2: 55885 | AF2: 56250 | AG2: 56615 | AH2: 56980 | AI2: 57346 | AJ2: 57711 | AK2: 58076 | AL2: 58441 | AM2: 58807 | AN2: 59172 | AO2: 59537 | AP2: 59902 | AQ2: 60268 | AR2: 60633 | AS2: 60998 | AT2: 61363 | AU2: 61729 | AV2: 62094 | AW2: 62459 | AX2: 62824 | AY2: 63190 | AZ2: 63555 | BA2: 63920 | BB2: 64285 | BC2: 64651 | BD2: 65016 | BE2: 65381 | BF2: 65746 | BG2: 66112 | BH2: 66477 | BI2: 66842 | BJ2: 67207 | BK2: 67573
B3: KẾT QUẢ ĐẦU TƯ
B4: NPV chủ đầu tư @ r%/năm | C4: =XNPV(INPUT!$C$4/100,WEB_CF!$M$2:$M$14,WEB_CF!$O$2:$O$14)*1000 -> -119394.12
B5: IRR chủ đầu tư (levered) | C5: =XIRR(WEB_CF!$M$2:$M$14,WEB_CF!$O$2:$O$14) -> 0.0029697567
B6: IRR dự án — TMĐT (unlevered) | C6: =XIRR(WEB_CF!$L$2:$L$14,WEB_CF!$O$2:$O$14) -> 0.0023980528
B7: NPV bán riêng | C7: =WEB_RESULT!$B$13*1000 -> -118893.35
B8: Lợi nhuận sau thuế hợp nhất | C8: =$C$154-$C$155 -> 1.2888964e+10
B9: Tổng mức đầu tư (gồm lãi vay) | C9: =$C$115+$C$144 -> 1.231766e+12
B10: A · DÒNG TIỀN HỢP NHẤT THEO NĂM (triệu đồng)
B11: Thực thu Bán hàng (gồm VAT) (+) | C11: =SUM(D11:BK11) -> 1481705816250 | D11: =SUM(D37:D49)+IF(AND(D34>0,SUM(TIENDO!$C$20:$O$20)<0.0001),D34,0)+IF(AND(D35>0,SUM(TIENDO!$C$36:$O$36)<0.0001),D35,0) -> 0 | E11: =SUM(E37:E49)+IF(AND(E34>0,SUM(TIENDO!$C$21:$O$21)<0.0001),E34,0)+IF(AND(E35>0,SUM(TIENDO!$C$37:$O$37)<0.0001),E35,0) -> 0 | F11: =SUM(F37:F49)+IF(AND(F34>0,SUM(TIENDO!$C$22:$O$22)<0.0001),F34,0)+IF(AND(F35>0,SUM(TIENDO!$C$38:$O$38)<0.0001),F35,0) -> 170883900000 | G11: =SUM(G37:G49)+IF(AND(G34>0,SUM(TIENDO!$C$23:$O$23)<0.0001),G34,0)+IF(AND(G35>0,SUM(TIENDO!$C$39:$O$39)<0.0001),G35,0) -> 938437417500 | H11: =SUM(H37:H49)+IF(AND(H34>0,SUM(TIENDO!$C$24:$O$24)<0.0001),H34,0)+IF(AND(H35>0,SUM(TIENDO!$C$40:$O$40)<0.0001),H35,0) -> 372384498750 | I11: =SUM(I37:I49)+IF(AND(I34>0,SUM(TIENDO!$C$25:$O$25)<0.0001),I34,0)+IF(AND(I35>0,SUM(TIENDO!$C$41:$O$41)<0.0001),I35,0) -> 0 | J11: =SUM(J37:J49)+IF(AND(J34>0,SUM(TIENDO!$C$26:$O$26)<0.0001),J34,0)+IF(AND(J35>0,SUM(TIENDO!$C$42:$O$42)<0.0001),J35,0) -> 0 | K11: =SUM(K37:K49)+IF(AND(K34>0,SUM(TIENDO!$C$27:$O$27)<0.0001),K34,0)+IF(AND(K35>0,SUM(TIENDO!$C$43:$O$43)<0.0001),K35,0) -> 0 | L11: =SUM(L37:L49)+IF(AND(L34>0,SUM(TIENDO!$C$28:$O$28)<0.0001),L34,0)+IF(AND(L35>0,SUM(TIENDO!$C$44:$O$44)<0.0001),L35,0) -> 0 | M11: =SUM(M37:M49)+IF(AND(M34>0,SUM(TIENDO!$C$29:$O$29)<0.0001),M34,0)+IF(AND(M35>0,SUM(TIENDO!$C$45:$O$45)<0.0001),M35,0) -> 0 | N11: =SUM(N37:N49)+IF(AND(N34>0,SUM(TIENDO!$C$30:$O$30)<0.0001),N34,0)+IF(AND(N35>0,SUM(TIENDO!$C$46:$O$46)<0.0001),N35,0) -> 0 | O11: =SUM(O37:O49)+IF(AND(O34>0,SUM(TIENDO!$C$31:$O$31)<0.0001),O34,0)+IF(AND(O35>0,SUM(TIENDO!$C$47:$O$47)<0.0001),O35,0) -> 0 | P11: =SUM(P37:P49)+IF(AND(P34>0,SUM(TIENDO!$C$32:$O$32)<0.0001),P34,0)+IF(AND(P35>0,SUM(TIENDO!$C$48:$O$48)<0.0001),P35,0) -> 0 | Q11: 0 | R11: 0 | S11: 0 | T11: 0 | U11: 0 | V11: 0 | W11: 0 | X11: 0 | Y11: 0 | Z11: 0 | AA11: 0 | AB11: 0 | AC11: 0 | AD11: 0 | AE11: 0 | AF11: 0 | AG11: 0 | AH11: 0 | AI11: 0 | AJ11: 0 | AK11: 0 | AL11: 0 | AM11: 0 | AN11: 0 | AO11: 0 | AP11: 0 | AQ11: 0 | AR11: 0 | AS11: 0 | AT11: 0 | AU11: 0 | AV11: 0 | AW11: 0 | AX11: 0 | AY11: 0 | AZ11: 0 | BA11: 0 | BB11: 0 | BC11: 0 | BD11: 0 | BE11: 0 | BF11: 0 | BG11: 0 | BH11: 0 | BI11: 0 | BJ11: 0 | BK11: 0
B12: Doanh thu Cho thuê (+) | C12: =SUM(D12:BK12) -> 0 | D12: =D56+D57+D58 -> 0 | E12: =E56+E57+E58 -> 0 | F12: =F56+F57+F58 -> 0 | G12: =G56+G57+G58 -> 0 | H12: =H56+H57+H58 -> 0 | I12: =I56+I57+I58 -> 0 | J12: =J56+J57+J58 -> 0 | K12: =K56+K57+K58 -> 0 | ... BK12: =BK56+BK57+BK58 -> 0
B13: (−) Chi đầu tư Bán hàng (tổng) | C13: =SUM(D13:BK13) -> 1192835671250 | D13: =D14+D15+D16+D17 -> 200000000000 | E13: =E14+E15+E16+E17 -> 215000000000 | F13: =F14+F15+F16+F17 -> 478456668500 | G13: =G14+G15+G16+G17 -> 236882835625 | H13: =H14+H15+H16+H17 -> 62496167125 | I13: =I14+I15+I16+I17 -> 0 | J13: =J14+J15+J16+J17 -> 0 | K13: =K14+K15+K16+K17 -> 0 | ... P13: =P14+P15+P16+P17 -> 0 | Q13: 0 | R13: 0 | S13: 0 | T13: 0 | U13: 0 | V13: 0 | W13: 0 | X13: 0 | Y13: 0 | Z13: 0 | AA13: 0 | AB13: 0 | AC13: 0 | AD13: 0 | AE13: 0 | AF13: 0 | AG13: 0 | AH13: 0 | AI13: 0 | AJ13: 0 | AK13: 0 | AL13: 0 | AM13: 0 | AN13: 0 | AO13: 0 | AP13: 0 | AQ13: 0 | AR13: 0 | AS13: 0 | AT13: 0 | AU13: 0 | AV13: 0 | AW13: 0 | AX13: 0 | AY13: 0 | AZ13: 0 | BA13: 0 | BB13: 0 | BC13: 0 | BD13: 0 | BE13: 0 | BF13: 0 | BG13: 0 | BH13: 0 | BI13: 0 | BJ13: 0 | BK13: 0
B14: ↳ Đất (chuyển nhượng + đền bù) | C14: =SUM(D14:BK14) -> 400000000000 | D14: =$C$124*(1-$C$106)*TIENDO!C3/100+$C$125*(1-$C$106)*TIENDO!C4/100 -> 200000000000 | E14: =$C$124*(1-$C$106)*TIENDO!D3/100+$C$125*(1-$C$106)*TIENDO!D4/100 -> 200000000000 | F14: =$C$124*(1-$C$106)*TIENDO!E3/100+$C$125*(1-$C$106)*TIENDO!E4/100 -> 0 | G14: =$C$124*(1-$C$106)*TIENDO!F3/100+$C$125*(1-$C$106)*TIENDO!F4/100 -> 0 | H14: =$C$124*(1-$C$106)*TIENDO!G3/100+$C$125*(1-$C$106)*TIENDO!G4/100 -> 0 | I14: =$C$124*(1-$C$106)*TIENDO!H3/100+$C$125*(1-$C$106)*TIENDO!H4/100 -> 0 | J14: =$C$124*(1-$C$106)*TIENDO!I3/100+$C$125*(1-$C$106)*TIENDO!I4/100 -> 0 | K14: =$C$124*(1-$C$106)*TIENDO!J3/100+$C$125*(1-$C$106)*TIENDO!J4/100 -> 0 | ... P14: =$C$124*(1-$C$106)*TIENDO!O3/100+$C$125*(1-$C$106)*TIENDO!O4/100 -> 0 | Q14: 0 | R14: 0 | S14: 0 | T14: 0 | U14: 0 | V14: 0 | W14: 0 | X14: 0 | Y14: 0 | Z14: 0 | AA14: 0 | AB14: 0 | AC14: 0 | AD14: 0 | AE14: 0 | AF14: 0 | AG14: 0 | AH14: 0 | AI14: 0 | AJ14: 0 | AK14: 0 | AL14: 0 | AM14: 0 | AN14: 0 | AO14: 0 | AP14: 0 | AQ14: 0 | AR14: 0 | AS14: 0 | AT14: 0 | AU14: 0 | AV14: 0 | AW14: 0 | AX14: 0 | AY14: 0 | AZ14: 0 | BA14: 0 | BB14: 0 | BC14: 0 | BD14: 0 | BE14: 0 | BF14: 0 | BG14: 0 | BH14: 0 | BI14: 0 | BJ14: 0 | BK14: 0
B15: ↳ Tiền sử dụng đất | C15: =SUM(D15:BK15) -> 289070000000 | D15: =$C$126*(1-$C$106)*TIENDO!C5/100 -> 0 | E15: =$C$126*(1-$C$106)*TIENDO!D5/100 -> 0 | F15: =$C$126*(1-$C$106)*TIENDO!E5/100 -> 289070000000 | G15: =$C$126*(1-$C$106)*TIENDO!F5/100 -> 0 | H15: =$C$126*(1-$C$106)*TIENDO!G5/100 -> 0 | I15: =$C$126*(1-$C$106)*TIENDO!H5/100 -> 0 | J15: =$C$126*(1-$C$106)*TIENDO!I5/100 -> 0 | K15: =$C$126*(1-$C$106)*TIENDO!J5/100 -> 0 | ... P15: =$C$126*(1-$C$106)*TIENDO!O5/100 -> 0 | Q15: 0 | R15: 0 | S15: 0 | T15: 0 | U15: 0 | V15: 0 | W15: 0 | X15: 0 | Y15: 0 | Z15: 0 | AA15: 0 | AB15: 0 | AC15: 0 | AD15: 0 | AE15: 0 | AF15: 0 | AG15: 0 | AH15: 0 | AI15: 0 | AJ15: 0 | AK15: 0 | AL15: 0 | AM15: 0 | AN15: 0 | AO15: 0 | AP15: 0 | AQ15: 0 | AR15: 0 | AS15: 0 | AT15: 0 | AU15: 0 | AV15: 0 | AW15: 0 | AX15: 0 | AY15: 0 | AZ15: 0 | BA15: 0 | BB15: 0 | BC15: 0 | BD15: 0 | BE15: 0 | BF15: 0 | BG15: 0 | BH15: 0 | BI15: 0 | BJ15: 0 | BK15: 0
B16: ↳ Chi phí pháp lý | C16: =SUM(D16:BK16) -> 60000000000 | D16: =$C$127*(1-$C$106)*TIENDO!C6/100 -> 0 | E16: =$C$127*(1-$C$106)*TIENDO!D6/100 -> 15000000000 | F16: =$C$127*(1-$C$106)*TIENDO!E6/100 -> 15000000000 | G16: =$C$127*(1-$C$106)*TIENDO!F6/100 -> 15000000000 | H16: =$C$127*(1-$C$106)*TIENDO!G6/100 -> 15000000000 | I16: =$C$127*(1-$C$106)*TIENDO!H6/100 -> 0 | J16: =$C$127*(1-$C$106)*TIENDO!I6/100 -> 0 | K16: =$C$127*(1-$C$106)*TIENDO!J6/100 -> 0 | ... P16: =$C$127*(1-$C$106)*TIENDO!O6/100 -> 0 | Q16: 0 | R16: 0 | S16: 0 | T16: 0 | U16: 0 | V16: 0 | W16: 0 | X16: 0 | Y16: 0 | Z16: 0 | AA16: 0 | AB16: 0 | AC16: 0 | AD16: 0 | AE16: 0 | AF16: 0 | AG16: 0 | AH16: 0 | AI16: 0 | AJ16: 0 | AK16: 0 | AL16: 0 | AM16: 0 | AN16: 0 | AO16: 0 | AP16: 0 | AQ16: 0 | AR16: 0 | AS16: 0 | AT16: 0 | AU16: 0 | AV16: 0 | AW16: 0 | AX16: 0 | AY16: 0 | AZ16: 0 | BA16: 0 | BB16: 0 | BC16: 0 | BD16: 0 | BE16: 0 | BF16: 0 | BG16: 0 | BH16: 0 | BI16: 0 | BJ16: 0 | BK16: 0
B17: ↳ CPXD all-in (hạ tầng+XD+tư vấn+dự phòng) | C17: =SUM(D17:BK17) -> 443765671250 | D17: =$C$128*(1-$C$106)*TIENDO!C7/100+$C$129*1*TIENDO!C8/100+$C$131*(1-$C$105)*TIENDO!C10/100+$C$132*(1-$C$105)*TIENDO!C11/100 -> 0 | E17: =$C$128*(1-$C$106)*TIENDO!D7/100+$C$129*1*TIENDO!D8/100+$C$131*(1-$C$105)*TIENDO!D10/100+$C$132*(1-$C$105)*TIENDO!D11/100 -> 0 | F17: =$C$128*(1-$C$106)*TIENDO!E7/100+$C$129*1*TIENDO!E8/100+$C$131*(1-$C$105)*TIENDO!E10/100+$C$132*(1-$C$105)*TIENDO!E11/100 -> 174386668500 | G17: =$C$128*(1-$C$106)*TIENDO!F7/100+$C$129*1*TIENDO!F8/100+$C$131*(1-$C$105)*TIENDO!F10/100+$C$132*(1-$C$105)*TIENDO!F11/100 -> 221882835625 | H17: =$C$128*(1-$C$106)*TIENDO!G7/100+$C$129*1*TIENDO!G8/100+$C$131*(1-$C$105)*TIENDO!G10/100+$C$132*(1-$C$105)*TIENDO!G11/100 -> 47496167125 | I17: =$C$128*(1-$C$106)*TIENDO!H7/100+$C$129*1*TIENDO!H8/100+$C$131*(1-$C$105)*TIENDO!H10/100+$C$132*(1-$C$105)*TIENDO!H11/100 -> 0 | J17: =$C$128*(1-$C$106)*TIENDO!I7/100+$C$129*1*TIENDO!I8/100+$C$131*(1-$C$105)*TIENDO!I10/100+$C$132*(1-$C$105)*TIENDO!I11/100 -> 0 | K17: =$C$128*(1-$C$106)*TIENDO!J7/100+$C$129*1*TIENDO!J8/100+$C$131*(1-$C$105)*TIENDO!J10/100+$C$132*(1-$C$105)*TIENDO!J11/100 -> 0 | ... P17: =$C$128*(1-$C$106)*TIENDO!O7/100+$C$129*1*TIENDO!O8/100+$C$131*(1-$C$105)*TIENDO!O10/100+$C$132*(1-$C$105)*TIENDO!O11/100 -> 0 | Q17: 0 | R17: 0 | S17: 0 | T17: 0 | U17: 0 | V17: 0 | W17: 0 | X17: 0 | Y17: 0 | Z17: 0 | AA17: 0 | AB17: 0 | AC17: 0 | AD17: 0 | AE17: 0 | AF17: 0 | AG17: 0 | AH17: 0 | AI17: 0 | AJ17: 0 | AK17: 0 | AL17: 0 | AM17: 0 | AN17: 0 | AO17: 0 | AP17: 0 | AQ17: 0 | AR17: 0 | AS17: 0 | AT17: 0 | AU17: 0 | AV17: 0 | AW17: 0 | AX17: 0 | AY17: 0 | AZ17: 0 | BA17: 0 | BB17: 0 | BC17: 0 | BD17: 0 | BE17: 0 | BF17: 0 | BG17: 0 | BH17: 0 | BI17: 0 | BJ17: 0 | BK17: 0
B18: (−) Chi phí hoạt động Bán hàng | C18: =SUM(D18:BK18) -> 2.5188999e+11 | D18: =D36*(INPUT!$C$118+INPUT!$C$119+INPUT!$C$120+INPUT!$C$121+INPUT!$C$123+INPUT!$C$124)/100+D11*INPUT!$C$122/100 -> 0 | E18: =E36*(INPUT!$C$118+INPUT!$C$119+INPUT!$C$120+INPUT!$C$121+INPUT!$C$123+INPUT!$C$124)/100+E11*INPUT!$C$122/100 -> 0 | F18: =F36*(INPUT!$C$118+INPUT!$C$119+INPUT!$C$120+INPUT!$C$121+INPUT!$C$123+INPUT!$C$124)/100+F11*INPUT!$C$122/100 -> 96036751800 | G18: =G36*(INPUT!$C$118+INPUT!$C$119+INPUT!$C$120+INPUT!$C$121+INPUT!$C$123+INPUT!$C$124)/100+G11*INPUT!$C$122/100 -> 102356608035 | H18: =H36*(INPUT!$C$118+INPUT!$C$119+INPUT!$C$120+INPUT!$C$121+INPUT!$C$123+INPUT!$C$124)/100+H11*INPUT!$C$122/100 -> 5.3496629e+10 | I18: =I36*(INPUT!$C$118+INPUT!$C$119+INPUT!$C$120+INPUT!$C$121+INPUT!$C$123+INPUT!$C$124)/100+I11*INPUT!$C$122/100 -> 0 | J18: =J36*(INPUT!$C$118+INPUT!$C$119+INPUT!$C$120+INPUT!$C$121+INPUT!$C$123+INPUT!$C$124)/100+J11*INPUT!$C$122/100 -> 0 | K18: =K36*(INPUT!$C$118+INPUT!$C$119+INPUT!$C$120+INPUT!$C$121+INPUT!$C$123+INPUT!$C$124)/100+K11*INPUT!$C$122/100 -> 0 | ... BK18: =BK36*(INPUT!$C$118+INPUT!$C$119+INPUT!$C$120+INPUT!$C$121+INPUT!$C$123+INPUT!$C$124)/100+BK11*INPUT!$C$122/100 -> 0
